Workbook

Sheet Project Summary
A1: Project Summary | E1: Notes
A3: Project Name:
A5: Civic Address:
A7: Units
A9: GFA
A10: NFA
A12: Notes
B14: Yellow Tabs require inputs

Sheet Inputs & Assumptions
A1: Inputs & Assumptions
A3: BUILDING
A4: Site Area
A5: GFA | C5: ='Sales Detail'!F39 -> 3690
A6: NFA | C6: =C7*C5 -> 3690
A7: Efficiency | C7: 1
A8: Common | C8: =C5-C6 -> 0
A9: Units | B9: Residential | C9: 20
B10: CRU | C10: 4 | N10: 7287
B11: Total | C11: =C9+C10 -> 24 | N11: 611
A12: Lockers | C12: 25 | N12: 1168
A13: Parking | C13: 97 | D13: =C13/C11 -> 4.0416667 | N13: 2922
N14: 211
A15: CONSTRUCTION | N15: 8337
A16: Cost per Square metre | C16: 800 | N16: 6462
A17: Construction Cost | C17: =C16*C5 -> 2952000 | N17: =SUM(N10:N16) -> 26998
A18: Construction Contingency | C18: 0.05
A19: Construction Fee | C19: 0
A21: DEVELOPMENT
A22: Project Management Fee | C22: 0.05
A23: Marketing | C23: 0.005
A24: Insurance | C24: 0.015
A26: PRESALES
A27: Presales | C27: 0.65
A28: Deposit Amount | C28: 0.15
A29: sold in | C29: 20 | D29: months starting month of construction
A30: Commissions | C30: 0.05
A31: SALES
A32: Sale Price per sqr metre | C32: 1850
A34: FINANCIAL
A35: LP Preferred Return | C35: 0.08
A36: LP Waterfall | C36: 0.5

Sheet Development Proforma
A1: FIFTH AVENUE - PROFORMA
B2: PROJECT: | C2: Seseh Project | G2: TYPE: | H2: Residential/Retail
B3: ADDRESS: | C3: Seseh - Bali | G3: Project #: | H3: TBD
B5: SUMMARY OF PROFORMA
B6: SITE AREA (SF) | C6: ='Inputs & Assumptions'!C4 -> 0
B8: BUILDING AREA (SF) | E8: =C11/C14 -> 184.5
B9: - Net Floor Area (NFA) | C9: ='Inputs & Assumptions'!C6 -> 3690 | G9: Number of Floors: | H9: 2
B10: - Common Area/Hall Space | C10: ='Inputs & Assumptions'!C8 -> 0 | G10: Constrcution: | H10: Concrete
B11: - Gross Floor Area (GFA) | C11: ='Inputs & Assumptions'!C5 -> 3690 | G11: Building Efficiency | H11: ='Inputs & Assumptions'!C7 -> 1
B13: UNITS
B14: - Residential | C14: ='Inputs & Assumptions'!C9 -> 20
B15: DEVELOPMENT BUDGET
B17: LAND | G17: Cost Buildable/Gross sqft
C18: Land Cost | H18: 400000
C19: Property purchase taxes
C20: Rezone/Predevelopment Costs | H20: 0
C21: Legal Fees
C23: SUBTOTAL | I23: =SUM(H18:H21) -> 400000
B25: CONSTRUCTION COSTS | G25: Cost Buildable/Gross sqr metre
C26: Construction Contract - Base Contract | G26: ='Inputs & Assumptions'!C16 -> 800 | H26: =G26*'Inputs & Assumptions'!C5 -> 2952000 | I26: (RBD Bare construction risk)
C27: Construction Contingency | G27: 0 | H27: =H26*G27 -> 0 | I27: (Fixed Rate)
C29: SUBTOTAL | I29: =SUM(H26:H27) -> 2952000
B31: CASH ALLOWANCES
C33: SUBTOTAL | I33: =SUM(H31:H32) -> 0
B35: CONSULTANTS
C36: Architectural Fees & Consultants | G36: Included in Construction cost
C37: Permit and DCC | G37: Included In construction cost
C38: Other consultants
E39: Landscape Artictect
E40: Structural Engineering
E41: Mechanical Engineering
E42: Electrical Engineering
E43: Civil Engineering
E44: Code Consultant
C45: Geotechnical Engineering
C46: Survey Costs
C48: SUBTOTAL | I48: =SUM(H36:H46) -> 0
B50: MUNICIPAL
C51: Rezoning and Developemnt Permit Fees
C52: Building Permit fees (if not in construction)
...

Sheet Cash Flow
A1: FIFTH AVENUE - CASHFLOW
B2: PROJECT: | C2: ='Development Proforma'!C2 -> Seseh Project | G2: TYPE: | H2: Residential
B3: ADDRESS: | C3: Coronation Ave, Kelowna | G3: Project #: | H3: ='Development Proforma'!H3 -> TBD
B5: ASSUMPTIONS
C6: Start Date: | D6: 46174
C7: Development Phase | D7: 11 | E7: months
C8: Construction Phase | D8: 12 | E8: months
J10: 0 | K10: 1 | L10: 2 | M10: 3 | N10: 4 | O10: 5 | P10: 6 | Q10: 7 | R10: 8 | S10: 9 | T10: 10 | U10: 11 | V10: 12 | W10: 13 | X10: 14 | Y10: 15 | Z10: 16 | AA10: 17 | AB10: 18 | AC10: 19 | AD10: 20 | AE10: 21 | AF10: 22 | AG10: 23 | AH10: 24 | AI10: 25 | AJ10: 26 | AK10: 27 | AL10: 28 | AM10: 29 | AN10: 30 | AO10: 31 | AP10: 32 | AQ10: 33 | AR10: 34 | AS10: 33 | AU10: Total | AW10: Check
J11: 46054 | K11: 46082 | L11: 46113 | M11: 46143 | N11: 46174 | O11: 46204 | P11: 46235 | Q11: 46266 | R11: 46296 | S11: 46327 | T11: 46357 | U11: 46388 | V11: 46419 | W11: 46447 | X11: 46478 | Y11: 46508 | Z11: 46539 | AA11: 46569 | AB11: 46600 | AC11: 46631 | AD11: 46661 | AE11: 46692 | AF11: 46722 | AG11: 46753 | AH11: 46784 | AI11: 46813 | AJ11: 46844 | AK11: 46874 | AL11: 46905 | AM11: 46935 | AN11: 46966 | AO11: 46997 | AP11: 47027 | AQ11: 47058 | AR11: 47088 | AS11: 47119
B12: COST SCHEDULE
B14: LAND
C15: ='Development Proforma'!C18 -> Land Cost | H15: ='Development Proforma'!H18 -> 400000 | M15: =H15 -> 400000 | AU15: =SUM(J15:AS15) -> 400000 | AW15: =IF(AU15=H15,"Y", "Error") -> Y
C16: Property purchase taxes | H16: ='Development Proforma'!H19 -> 0 | AU16: =SUM(J16:AS16) -> 0 | AW16: =IF(AU16=H16,"Y", "Error") -> Y
C17: Rezone/Predevelopment Costs | H17: ='Development Proforma'!H20 -> 0 | AU17: =SUM(J17:AS17) -> 0 | AW17: =IF(AU17=H17,"Y", "Error") -> Y
C18: Legal Fees | H18: ='Development Proforma'!H21 -> 0 | AU18: =SUM(J18:AS18) -> 0 | AW18: =IF(AU18=H18,"Y", "Error") -> Y
B19: CONSTRUCTION COSTS | AU19: =SUM(J19:AS19) -> 0
C20: Construction Contract - Base Contract | H20: ='Development Proforma'!H26 -> 2952000 | N20: =$H$20/$D$8 -> 246000 | O20: =$H$20/$D$8 -> 246000 | P20: =$H$20/$D$8 -> 246000 | Q20: =$H$20/$D$8 -> 246000 | R20: =$H$20/$D$8 -> 246000 | S20: =$H$20/$D$8 -> 246000 | T20: =$H$20/$D$8 -> 246000 | U20: =$H$20/$D$8 -> 246000 | ... Y20: =$H$20/$D$8 -> 246000 | AU20: =SUM(J20:AS20) -> 2952000 | AW20: =IF(AU20=H20,"Y", "Error") -> Y
AU21: =SUM(J21:AS21) -> 0 | AW21: =IF(AU21=H21,"Y", "Error") -> Y
C22: Architectural Fees | H22: ='Development Proforma'!H39 -> 0 | AU22: =SUM(J22:AS22) -> 0 | AW22: =IF(AU22=H22,"Y", "Error") -> Y
C23: Landscape Artictect | H23: ='Development Proforma'!H40 -> 0 | AU23: =SUM(J23:AS23) -> 0 | AW23: =IF(AU23=H23,"Y", "Error") -> Y
C24: Structural Engineering | H24: ='Development Proforma'!H41 -> 0 | AU24: =SUM(J24:AS24) -> 0 | AW24: =IF(AU24=H24,"Y", "Error") -> Y
C25: Mechanical Engineering | H25: ='Development Proforma'!H42 -> 0 | AU25: =SUM(J25:AS25) -> 0 | AW25: =IF(AU25=H25,"Y", "Error") -> Y
C26: Electrical Engineering | H26: ='Development Proforma'!H43 -> 0 | AU26: =SUM(J26:AS26) -> 0 | AW26: =IF(AU26=H26,"Y", "Error") -> Y
C27: Civil Engineering | H27: ='Development Proforma'!H44 -> 0 | AU27: =SUM(J27:AS27) -> 0 | AW27: =IF(AU27=H27,"Y", "Error") -> Y
C28: Code Consultant | H28: ='Development Proforma'!H45 -> 0 | AU28: =SUM(J28:AS28) -> 0 | AW28: =IF(AU28=H28,"Y", "Error") -> Y
C29: Geotechnical Engineering | H29: ='Development Proforma'!H46 -> 0 | AU29: =SUM(J29:AS29) -> 0 | AW29: =IF(AU29=H29,"Y", "Error") -> Y
C30: Survey Costs | H30: ='Development Proforma'!H46 -> 0 | AU30: =SUM(J30:AS30) -> 0 | AW30: =IF(AU30=H30,"Y", "Error") -> Y
B31: MUNICIPAL | AU31: =SUM(J31:AS31) -> 0 | AW31: =IF(AU31=H31,"Y", "Error") -> Y
C32: Rezoning and Developemnt Permit Fees | H32: ='Development Proforma'!H51 -> 0 | AU32: =SUM(J32:AS32) -> 0 | AW32: =IF(AU32=H32,"Y", "Error") -> Y
C33: Building Permit fees (if not in construction) | H33: ='Development Proforma'!H52 -> 0 | AU33: =SUM(J33:AS33) -> 0 | AW33: =IF(AU33=H33,"Y", "Error") -> Y
C34: Other municipal fees | H34: ='Development Proforma'!H53 -> 0 | AU34: =SUM(J34:AS34) -> 0 | AW34: =IF(AU34=H34,"Y", "Error") -> Y
B35: CONSULTING | AU35: =SUM(J35:AS35) -> 0
C36: Project Management Fee | H36: ='Development Proforma'!H58 -> 321000 | M36: =H36*0.5 -> 160500 | N36: =($H$36-$M$36)/12 -> 13375 | O36: =($H$36-$M$36)/12 -> 13375 | P36: =($H$36-$M$36)/12 -> 13375 | Q36: =($H$36-$M$36)/12 -> 13375 | R36: =($H$36-$M$36)/12 -> 13375 | S36: =($H$36-$M$36)/12 -> 13375 | T36: =($H$36-$M$36)/12 -> 13375 | U36: =($H$36-$M$36)/12 -> 13375 | ... Y36: =($H$36-$M$36)/12 -> 13375 | AU36: =SUM(J36:AS36) -> 321000 | AW36: =IF(AU36=H36,"Y", "Error") -> Y
C37: Marketing | H37: ='Development Proforma'!H59 -> 128400 | J37: =$H$37/17 -> 7552.9412 | K37: =$H$37/17 -> 7552.9412 | L37: =$H$37/17 -> 7552.9412 | M37: =$H$37/17 -> 7552.9412 | N37: =$H$37/17 -> 7552.9412 | O37: =$H$37/17 -> 7552.9412 | P37: =$H$37/17 -> 7552.9412 | Q37: =$H$37/17 -> 7552.9412 | ... Z37: =$H$37/17 -> 7552.9412 | AU37: =SUM(J37:AS37) -> 128400 | AW37: =IF(AU37=H37,"Y", "Error") -> Y
B38: SUPPORT SERVICES | AU38: =SUM(J38:AS38) -> 0
C39: PT PMA SETUP | AU39: =SUM(J39:AS39) -> 0 | AW39: =IF(AU39=H39,"Y", "Error") -> Y
C40: Deed Amendment | AU40: =SUM(J40:AS40) -> 0 | AW40: =IF(AU40=H40,"Y", "Error") -> Y
C41: Villa Licensing | AU41: =SUM(J41:AS41) -> 0 | AW41: =IF(AU41=H41,"Y", "Error") -> Y
C42: NPWPD Registration | AU42: =SUM(J42:AS42) -> 0 | AW42: =IF(AU42=H42,"Y", "Error") -> Y
C43: Annual Legal Compliance | AU43: =SUM(J43:AS43) -> 0 | AW43: =IF(AU43=H43,"Y", "Error") -> Y
...

Sheet Sales Detail
A1: FIFTH AVENUE - SALES DETAILS
B2: PROJECT: | C2: ='Development Proforma'!C2 -> Seseh Project | G2: TYPE: | H2: Residential | R2: Second Option
B3: ADDRESS: | C3: Coronation Ave, Kelowna | G3: Project #: | H3: ='Development Proforma'!H3 -> TBD
R4: Monthly Payments | S4: =(75/11)/100 -> 0.068181818
B5: ASSUMPTIONS
C7: Pre-sales | D7: ='Inputs & Assumptions'!C27 -> 0.65
C8: Deposit | D8: ='Inputs & Assumptions'!C28 -> 0.15 | F8: Construction Start (10%) | H8: 0.1
C9: Pre-Sales Period | D9: 5 | E9: Months | F9: Monthly Payments (6.8%) | H9: =S4 -> 0.068181818
C10: Commissions | D10: ='Inputs & Assumptions'!C18 -> 0.05
C11: Discounted | D11: 0.93
J12: 1 | K12: 2 | L12: 3 | M12: 4 | N12: 5 | O12: 6 | P12: 7 | Q12: 8 | R12: 9 | S12: 10 | T12: 11 | U12: 12 | V12: 13 | W12: 14 | X12: 15 | Y12: 16 | Z12: 17 | AA12: 18 | AB12: 19 | AC12: 20 | AD12: 21 | AE12: 22 | AF12: 23 | AG12: 24 | AH12: 25 | AI12: 26 | AJ12: 27 | AK12: 28 | AL12: 29 | AM12: 30 | AN12: 31 | AO12: 32 | AP12: 33 | AQ12: 34 | AR12: 35 | AS12: 36 | AU12: Total | AW12: Check
J13: ='Cash Flow'!J11 -> 46054 | K13: ='Cash Flow'!K11 -> 46082 | L13: ='Cash Flow'!L11 -> 46113 | M13: ='Cash Flow'!M11 -> 46143 | N13: ='Cash Flow'!N11 -> 46174 | O13: ='Cash Flow'!O11 -> 46204 | P13: ='Cash Flow'!P11 -> 46235 | Q13: ='Cash Flow'!Q11 -> 46266 | ... AS13: ='Cash Flow'!AS11 -> 47119
B14: SALE PLAN
B16: Percentage | D16: 65% of pre sales done before construction | K16: ='Development Proforma'!I96 -> 2830587.4 | AI16: 0 | AJ16: 0 | AK16: 0.1 | AL16: 0.1 | AM16: 0.1
B17: Contract Value | D17: Recognised on completion | AI17: =AI16*$E$31 -> 0 | AJ17: =AJ16*$E$31 -> 0 | AK17: =AK16*$E$31 -> 0 | AL17: =AL16*$E$31 -> 0 | AM17: =AM16*$E$31 -> 0
B18: Comissions | M18: =M19*M22 -> 21229.405 | N18: =N19*N22 -> 14152.937 | O18: =O19*O22 -> 9649.7296 | P18: =P19*P22 -> 9649.7296 | Q18: =Q19*Q22 -> 9649.7296 | R18: =R19*R22 -> 9649.7296 | S18: =S19*S22 -> 9649.7296 | T18: =T19*T22 -> 9649.7296 | ... Y18: =Y19*Y22 -> 9649.7296
B19: Deposits | D19: 15% of Pre-sale | M19: =K16*D8 -> 424588.1 | N19: =K16*H8 -> 283058.74 | O19: =$K$16*$S$4 -> 192994.59 | P19: =$K$16*$S$4 -> 192994.59 | Q19: =$K$16*$S$4 -> 192994.59 | R19: =$K$16*$S$4 -> 192994.59 | S19: =$K$16*$S$4 -> 192994.59 | T19: =$K$16*$S$4 -> 192994.59 | U19: =$K$16*$S$4 -> 192994.59 | V19: =$K$16*$S$4 -> 192994.59 | ... Y19: =$K$16*$S$4 -> 192994.59 | AI19: =$E$31*AI16*$D$8 -> 0 | AJ19: =$E$31*AJ16*$D$8 -> 0 | AK19: =$E$31*AK16*$D$8 -> 0 | AL19: =$E$31*AL16*$D$8 -> 0 | AM19: =$E$31*AM16*$D$8 -> 0
B20: Revenue Recognition | K20: =SUM(M20:Y20) -> 2689058 | M20: =M19-M18 -> 403358.7 | N20: =N19-N18 -> 268905.8 | O20: =O19-O18 -> 183344.86 | P20: =P19-P18 -> 183344.86 | Q20: =Q19-Q18 -> 183344.86 | R20: =R19-R18 -> 183344.86 | S20: =S19-S18 -> 183344.86 | T20: =T19-T18 -> 183344.86 | ... Y20: =Y19-Y18 -> 183344.86
B22: Commissions (percentage) | M22: =$D$10 -> 0.05 | N22: =$D$10 -> 0.05 | O22: =$D$10 -> 0.05 | P22: =$D$10 -> 0.05 | Q22: =$D$10 -> 0.05 | R22: =$D$10 -> 0.05 | S22: =$D$10 -> 0.05 | T22: =$D$10 -> 0.05 | ... Y22: =$D$10 -> 0.05 | AI22: =$E$31*AI16*$D$10 -> 0 | AJ22: =$E$31*AJ16*$D$10 -> 0 | AK22: =$E$31*AK16*$D$10 -> 0 | AL22: =$E$31*AL16*$D$10 -> 0 | AM22: =$E$31*AM16*$D$10 -> 0
A25: {='Cash Flow'!H6:X63} -> #VALUE!
C34: Unit Mix | D34: Number of units | E34: Unit Sqr m | F34: Total Sqr m | G34: price per sqr m | H34: price per unit | I34: Total Revenue
C35: 2 bedrooms | D35: 13 | E35: 180 | F35: =E35*D35 -> 2340 | G35: =H35/E35 -> 1638.8889 | H35: 295000 | I35: =H35*D35 -> 3835000
C36: 3 bedrooms | D36: 4 | E36: 180 | F36: =E36*D36 -> 720 | G36: =H36/E36 -> 1944.4444 | H36: 350000 | I36: =H36*D36 -> 1400000
C37: 4 bedrooms | D37: 3 | E37: 210 | F37: =E37*D37 -> 630 | G37: =H37/E37 -> 1880.9524 | H37: 395000 | I37: =H37*D37 -> 1185000
C39: Total | D39: =SUM(D35:D37) -> 20 | F39: =SUM(F35:F37) -> 3690 | I39: =SUM(I35:I37) -> 6420000
